Workbook
Name Actividad: #REF!
Name BASE: '[1]CONDUCTORES Y MATERIALES'!#REF!
Name BASE: '[2]CONDUCTORES Y MATERIALES'!#REF!
Name Base_de_Datos_PF: #REF!
Name BD_Servicios_CPO: #REF!
Name ESTRUCTURA: '[1]TABLA DE ESTRUCTURA'!$A$3:$K$1048576
Name ESTRUCTURA: '[2]TABLA DE ESTRUCTURA'!$A$3:$K$1048576
Name geees: #REF!
Name HOMOLOGADOS: #REF!
Name HOMOLOGADOS: #REF!
Name NO: #REF!
Name REPLANTEO: #REF!
Name SI: #REF!
Name Summary: #REF!
Name Summary: #REF!
Name ta: #REF!
Name Tb_Estructura: #REF!
Name Tb_Materiales: #REF!
Name xxxx: #REF!

Sheet peso de familias
A1: UU_TT | B1: Descripcion | C1: UNIDAD | D1: ACT_PRI | E1: peso de familias
A2: 1000568 | B2: Cobertor de Líneas MT 12.5kV MVLC 4/0 | C2: Mts. | D2: Instalación | E2: Material
A3: 1011408 | B3: Poste de madera de 60 Pies Clase 2 | C3: Und. | D3: Instalación | E3: Izaje Mt.
A4: AL-BT1 | B4: INSTALACIÓN DE LÍNEA DE BAJA TENSIÓN EN ALINEAMIENTO | C4: Und. | D4: Instalación | E4: Armado Bt.
A5: C45-MT1 | B5: INSTALACIÓN DE CRUCETA DOBLE DE ACERO PARA MEDIA TENSIÓN (C/SOPORTES A 45°) | C5: Und. | D5: Instalación | E5: Armado Mt.
A6: CA-101(465) | B6: CONEXIÓN DE CUT-OUT A 4651 | C6: Und. | D6: Instalación | E6: Armado Mt.
A7: CDA-MT11 | B7: INSTALACIÓN DE CRUCETA DOBLE DE ACERO PARA MEDIA TENSIÓN (CRUCETA DE 8') | C7: Und. | D7: Instalación | E7: Armado Mt.
A8: CSA-MT1 | B8: INSTALACIÓN DE CRUCETA SIMPLE DE ACERO PARA MEDIA TENSIÓN (CRUCETA DE 8') | C8: Und. | D8: Instalación | E8: Armado Mt.
A9: CV1-MT11 | B9: INSTALACIÓN DE CRUCETA SIMPLE DE ACERO EN VOLADIZO PARA MEDIA TENSIÓN(CRUCETA DE 8) | C9: Und. | D9: Instalación | E9: Armado Mt.
A10: CV2-MT1 | B10: INSTALACIÓN DE CRUCETA DE ACERO EN VOLADIZO PARA MEDIA TENSIÓN(2 NIVELES ) | C10: Und. | D10: Instalación | E10: Armado Mt.
A11: CV3-MT1 | B11: INSTALACIÓN DE CRUCETA DE ACERO EN VOLADIZO EN TRES NIVELES PARA MEDIA TENSION | C11: Und. | D11: Instalación | E11: Armado Mt.
A12: CV4-MT11 | B12: INSTALACIÓN DE CRUCETA DOBLE DE ACERO EN VOLADIZO PARA MEDIA TENSIÓN(CRUCETA DE 8) | C12: Und. | D12: Instalación | E12: Armado Mt.
A13: CV5-MT1(10) | B13: INSTALACIÓN DE CRUCETA DOBLE DE ACERO EN VOLADIZO PARA MEDIA TENSIÓN (2 NIVELES) | C13: Und. | D13: Instalación | E13: Armado Mt.
A14: CV6-MT1 | B14: INSTALACIÓN DE CRUCETA DE ACERO DOBLE EN VOLADIZO EN TRES NIVELES PARA MEDIA TENSION | C14: Und. | D14: Instalación | E14: Armado Mt.
A15: CV8-MT1 | B15: INSTALACIÓN DE CRUCETA DE ACERO SIMPLE EN VOLADIZO DE 10´ | C15: Und. | D15: Instalación | E15: Armado Mt.
... A210: VA-MT(T) | B210: TRANSFERENCIA DE CABLE DE VIENTO AEREO | C210: Und. | D210: Transferencia | E210: Armado Mt.

Sheet TD GENERAL
A2: MAT | B2: (Todas)
A4: ACTIVIDAD | B4: Código | C4: Descripción de la actividad | D4: UNIDAD | E4: dddd
B5: 1AC-103 | C5: INSTALACIÓN DE ACOMETIDA 120V RED ANTIFRAUDE CON BASE, DESDE LA CAJA DERIVADORA | D5: UND | E5: =+VLOOKUP($B5,Tabla3[UU_TT],1,FALSE) -> 1AC-103
B6: 1AC-104 | C6: INSTALACIÓN DE ACOMETIDA 240V RED ANTIFRAUDE CON BASE, DESDE LA CAJA DERIVADORA | D6: UND | E6: =+VLOOKUP($B6,Tabla3[UU_TT],1,FALSE) -> 1AC-104
B7: 1AC-105 | C7: INSTALACIÓN DE ACOMETIDA 120V DESDE RED ANTIFRAUDE CON SMCA CON DISPLAY, TOMACORRIENTE. | D7: UND | E7: =+VLOOKUP($B7,Tabla3[UU_TT],1,FALSE) -> 1AC-105
B8: 1AC-106 | C8: INSTALACIÓN DE ACOMETIDA 240V DESDE RED ANTIFRAUDE CON SMCA CON DISPLAY, TOMACORRIENTE. | D8: UND | E8: =+VLOOKUP($B8,Tabla3[UU_TT],1,FALSE) -> 1AC-106
B9: 1AL-BT | C9: INSTALACIÓNALACIÓN LÍNEA DE BT EN ALINEAMIENTO | D9: UND | E9: =+VLOOKUP($B9,Tabla3[UU_TT],1,FALSE) -> 1AL-BT
B10: 1AP-101 | C10: Instalación Luminaria Con Soporte de 6' en Poste de MT & BT Hasta 400 W | D10: UND | E10: =+VLOOKUP($B10,Tabla3[UU_TT],1,FALSE) -> 1AP-101
B11: 1AP-102 | C11: Instalación Luminaria Con Soporte de 12' en Poste de MT & BT Hasta 400 W | D11: UND | E11: =+VLOOKUP($B11,Tabla3[UU_TT],1,FALSE) -> 1AP-102
B12: 1AP-108 | C12: INSTALACIÓN DE BALASTRO O INGNITOR (ARRANCADOR) | D12: UND | E12: =+VLOOKUP($B12,Tabla3[UU_TT],1,FALSE) -> #N/A
B13: 1AP-109 | C13: INSTALACION DE TABLERO O CAJA DE CONTROL DE CONJUNTO DE LUMINARIAS | D13: UND | E13: =+VLOOKUP($B13,Tabla3[UU_TT],1,FALSE) -> #N/A
B14: 1AP-110 | C14: INSTALACIÓN DE CONTACTOR DE LUMINARIAS EN POSTE (RELAY) | D14: UND | E14: =+VLOOKUP($B14,Tabla3[UU_TT],1,FALSE) -> #N/A
B15: 1BCON-01 | C15: INSTALACIÓN SOPORTE DE BANCO DE CONDENSADORES. | D15: UND | E15: =+VLOOKUP($B15,Tabla3[UU_TT],1,FALSE) -> 1BCON-01
B16: 1BCON-02 | C16: INSTALACIÓN DE CONDENSADORES O CAPACITOR, NO INCLUYE PROTECCIÓN | D16: UND | E16: =+VLOOKUP($B16,Tabla3[UU_TT],1,FALSE) -> 1BCON-02
... B725: VA-MT1 | C725: INSTALACIÓN CABLE RETENIDA AEREA DE POSTE A POSTE (MT) | D725: UND | E725: =+VLOOKUP($B725,Tabla3[UU_TT],1,FALSE) -> VA-MT1
A726: REMOCION | B726: 1AC-103 | C726: INSTALACIÓN DE ACOMETIDA 120V RED ANTIFRAUDE CON BASE, DESDE LA CAJA DERIVADORA | D726: UND | E726: =+VLOOKUP($B726,Tabla3[UU_TT],1,FALSE) -> 1AC-103
A727: REMOCION | B727: 3AC-103 | C727: DESMONTAJE DE ACOMETIDA 120V RED ANTIFRAUDE CON BASE, DESDE LA CAJA DERIVADORA | D727: UND | E727: =+VLOOKUP($B727,Tabla3[UU_TT],1,FALSE) -> #N/A
A728: REMOCION | B728: 3AC-104 | C728: DESMONTAJE DE ACOMETIDA 240V RED ANTIFRAUDE CON BASE, DESDE LA CAJA DERIVADORA | D728: UND | E728: =+VLOOKUP($B728,Tabla3[UU_TT],1,FALSE) -> #N/A
A729: REMOCION | B729: 3AC-105 | C729: DESMONTAJE DE ACOMETIDA 120V DESDE RED ANTIFRAUDE CON SMCA CON DISPLAY, TOMACORRIENTE | D729: UND | E729: =+VLOOKUP($B729,Tabla3[UU_TT],1,FALSE) -> #N/A
A730: REMOCION | B730: 3AC-106 | C730: DESMONTAJE DE ACOMETIDA 240V DESDE RED ANTIFRAUDE CON SMCA CON DISPLAY, TOMACORRIENTE. | D730: UND | E730: =+VLOOKUP($B730,Tabla3[UU_TT],1,FALSE) -> #N/A
A731: REMOCION | B731: 3AL-BT | C731: DESMONTAJE LÍNEA DE BT EN ALINEAMIENTO | D731: UND | E731: =+VLOOKUP($B731,Tabla3[UU_TT],1,FALSE) -> #N/A
A732: REMOCION | B732: 3BCON-01 | C732: DESMONTAJE SOPORTE DE BANCO DE CONDENSADORES. | D732: UND | E732: =+VLOOKUP($B732,Tabla3[UU_TT],1,FALSE) -> #N/A
A733: REMOCION | B733: 3BCON-02 | C733: DESMONTAJE DE CONDENSADORES O CAPACITOR, NO INCLUYE PROTECCIÓN | D733: UND | E733: =+VLOOKUP($B733,Tabla3[UU_TT],1,FALSE) -> #N/A
A734: REMOCION | B734: 3BOM-01 | C734: Desmontaje de Bombillas Hasta 400 W | D734: UND | E734: =+VLOOKUP($B734,Tabla3[UU_TT],1,FALSE) -> #N/A
A735: REMOCION | B735: 3BOM-02 | C735: Desmontaje de Bombillas Mayor a 400 W | D735: UND | E735: =+VLOOKUP($B735,Tabla3[UU_TT],1,FALSE) -> #N/A
A736: REMOCION | B736: 3BREGU-01 | C736: DESMONTAJE DE BASE PARA BANCO DE REGULADORES/BOOSTER HASTA 3 X 75KV | D736: UND | E736: =+VLOOKUP($B736,Tabla3[UU_TT],1,FALSE) -> #N/A
A737: REMOCION | B737: 3BREGU-02 | C737: DESMONTAJE DE BASE PARA BANCO DE REGULADORES/BOOSTER HASTA 3 X 225KV | D737: UND | E737: =+VLOOKUP($B737,Tabla3[UU_TT],1,FALSE) -> #N/A
... A1570: (en blanco) | B1570: (en blanco) | C1570: (en blanco) | D1570: (en blanco) | E1570: =+VLOOKUP($B1570,Tabla3[UU_TT],1,FALSE) -> #N/A
A1571: Total general | E1571: =+VLOOKUP($B1571,Tabla3[UU_TT],1,FALSE) -> #N/A

Sheet Hoja7
B3: Código | C3: Descripción de la actividad | D3: UNIDAD
B4: 1MT-208 | C4: INSTALACIÓN LINEA 2Ø,ALINEAMIENTO CON DERIVACION 1Ø | D4: UND
B5: 1MT-209 | C5: INSTALACIÓN LINEA 2Ø,ALINEAMIENTO CON DERIVACION 2Ø
B6: 1MT-210 | C6: INSTALACIÓN FIN LINEA 2Ø, VERTICAL CON DERIVACION 1Ø
B7: 1MT-211 | C7: INSTALACIÓN FIN LINEA 2Ø, HORIZONTAL DERIVACION 1Ø

Sheet Todo los proyecto
A3: Código | B3: Descripción de la actividad
A4: ACMCA-240V1 | B4: INSTALACIÓN.ACOM.240V EN SCMA CON MED.DIPLAY Y TC. | C4: =+VLOOKUP($A4,TB_CALCULO_MAT[UU_TT],1,) -> ACMCA-240V1
A5: AL-BT1 | B5: INSTALACIÓN DE LÍNEA DE BAJA TENSIÓN EN ALINEAMIENTO | C5: =+VLOOKUP($A5,TB_CALCULO_MAT[UU_TT],1,) -> AL-BT1
A6: AL-BT3 | B6: REM. LINEA DE BT EN ALINEAMIENTO | C6: =+VLOOKUP($A6,TB_CALCULO_MAT[UU_TT],1,) -> #N/A
A7: AP-1032 | B7: TRANSFERENCIA LUMINARIA BRAZO 6' EN POSTE | C7: =+VLOOKUP($A7,TB_CALCULO_MAT[UU_TT],1,) -> #N/A
A8: AP-1033 | B8: REM LUMI. COMPL. C/SOPORTE DE 6' EN POSTE DE MT/BT | C8: =+VLOOKUP($A8,TB_CALCULO_MAT[UU_TT],1,) -> #N/A
A9: AP-LED1 | B9: INSTALACIÓN LUMINARIA TIPO LED 120W 240 V, CON SOPORTE DE 6 | C9: =+VLOOKUP($A9,TB_CALCULO_MAT[UU_TT],1,) -> AP-LED1
A10: BT-201-A1 | B10: INSTALACIÓN DE JUMPER AEREO TRIPLEX 4/0 -4/0 | C10: =+VLOOKUP($A10,TB_CALCULO_MAT[UU_TT],1,) -> BT-201-A1
A11: BT-201-B1 | B11: INSTALACIÓN DE JUMPER AEREO TRIPLEX 2/0 -2/0 | C11: =+VLOOKUP($A11,TB_CALCULO_MAT[UU_TT],1,) -> BT-201-B1
A12: BT-201-C1 | B12: INSTALACIÓN DE JUMPER AEREO TRIPLEX 4/0 -2/0 | C12: =+VLOOKUP($A12,TB_CALCULO_MAT[UU_TT],1,) -> BT-201-C1
A13: CAJ-1033 | B13: REMOCION DE CAJA DERIVADORA AF (30 SALIDAS) | C13: =+VLOOKUP($A13,TB_CALCULO_MAT[UU_TT],1,) -> #N/A
A14: CC-2/0-2/01 | B14: INSTALACIÓN DE CONEXIÓN 2/0 - 2/0 | C14: =+VLOOKUP($A14,TB_CALCULO_MAT[UU_TT],1,) -> CC-2/0-2/01
A15: CC-4/0-2/01 | B15: INSTALACIÓN DE CONEXIÓN 4/0 - 2/0 | C15: =+VLOOKUP($A15,TB_CALCULO_MAT[UU_TT],1,) -> CC-4/0-2/01
... A228: (en blanco) | B228: (en blanco) | C228: =+VLOOKUP($A228,TB_CALCULO_MAT[UU_TT],1,) -> #N/A
A229: Total general | C229: =+VLOOKUP($A229,TB_CALCULO_MAT[UU_TT],1,) -> #N/A

Sheet Completas
A1: UUTT -LOTE_18 | B1: DESCRIPCION CONTRATO | C1: Cod-Material | D1: Codigo SAP | E1: Descripcion material contrato | F1: Unidad | G1: Cantidad
A2: 1AL-BT | B2: Instalación de Línea de Baja Tensión en Alineamiento | C2: W-7A | D2: 1000050 | E2: Alambre de amarre #4 AWG solido de aluminio | F2: Mts. | G2: 1
A3: 1AL-BT | B3: Instalación de Línea de Baja Tensión en Alineamiento | C3: CP-02C | D3: 1009782 | E3: Cable de acero cobreado desnudo #2 AWG; 7 hilos | F3: Mts. | G3: 1
A4: 1AL-BT | B4: Instalación de Línea de Baja Tensión en Alineamiento | C4: AC-11A | D4: 1000000 | E4: Aislad T/Carr 3x3-1/8 76x80mm 11/16 53-2 | F4: Und. | G4: 1
A5: 1AL-BT | B5: Instalación de Línea de Baja Tensión en Alineamiento | C5: W-9C | D5: 1002185 | E5: ARANDELA CUADRADA 3" X 3'' PARA TORNILLO DE 5/8"-3/4'' | F5: Und. | G5: 1
A6: 1AL-BT | B6: Instalación de Línea de Baja Tensión en Alineamiento | C6: W-10C | D6: 1002205 | E6: ARANDELA DE PRESION P/TORNILLO 5/8'' | F6: Und. | G6: 1
A7: 1AL-BT | B7: Instalación de Línea de Baja Tensión en Alineamiento | C7: C-39C | D7: 1009963 | E7: CONECTOR CUÑA PRESION 2/0 AWG A 2 CU AWG | F7: Und. | G7: 1
A8: 1AL-BT | B8: Instalación de Línea de Baja Tensión en Alineamiento | C8: GCT-ST1 | D8: 1009789 | E8: GRAPA DE CONEXIÓN DOBLE CABLE DE TIERRA SIN TORNILLO | F8: Und. | G8: 1
A9: 1AL-BT | B9: Instalación de Línea de Baja Tensión en Alineamiento | C9: S-1D | D9: 1002349 | E9: Tornillo P/ Aislador T/ Carrete 5/8"x16" | F9: Und. | G9: 1
A10: 1CDA-MT | B10: Instalación de Cruceta Doble de Acero para Media Tensión (cruceta de 8') | C10: W-10C | D10: 1002205 | E10: ARANDELA DE PRESION P/TORNILLO 5/8'' | F10: Und. | G10: 18
A11: 1CDA-MT | B11: Instalación de Cruceta Doble de Acero para Media Tensión (cruceta de 8') | C11: W-10B | D11: 1002201 | E11: Arandela de presión para tornillo de 1/2” | F11: Und. | G11: 1
A12: 1CDA-MT | B12: Instalación de Cruceta Doble de Acero para Media Tensión (cruceta de 8') | C12: C-20D | D12: 1002083 | E12: Cruceta de acero galvanizado, perfil "L", de 3"x 3"x 1/4" x 8' | F12: Und. | G12: 2
A13: 1CDA-MT | B13: Instalación de Cruceta Doble de Acero para Media Tensión (cruceta de 8') | C13: B-1C | D13: 1002283 | E13: Tornillo de espaciamiento acero galvanizado 5/8” x 12” | F13: Und. | G13: 5
... A129: 1HA-105B | B129: Instalación de Retenida aérea simple en Media Tension | C129: E-1B | D129: 1002398 | E129: TUERCA OJO CON GUARDACABO RECTO 5/8" 55.6 KN | F129: Und. | G129: 1
A130: 1HA-105B | B130: Instalación de Retenida aérea simple en Media Tension | C130: G-2A | D130: #N/A | E130: Tornillo guardacabo recto 5/8" x 12” | F130: Und. | G130: 1
A131: 1MT-101 | B131: Instalación de Montaje 1ø Línea con Ángulo de 0º a 5º | C131: W-7A | D131: 1000050 | E131: Alambre de amarre #4 AWG solido de aluminio | F131: Mts. | G131: 2
A132: 1MT-101 | B132: Instalación de Montaje 1ø Línea con Ángulo de 0º a 5º | C132: CP-02C | D132: 1009782 | E132: Cable de acero cobreado desnudo #2 AWG; 7 hilos | F132: Mts. | G132: 1
A133: 1MT-101 | B133: Instalación de Montaje 1ø Línea con Ángulo de 0º a 5º | C133: AC-11A | D133: 1000000 | E133: Aislad T/Carr 3x3-1/8 76x80mm 11/16 53-2 | F133: Und. | G133: 1
A134: 1MT-101 | B134: Instalación de Montaje 1ø Línea con Ángulo de 0º a 5º | C134: AR-12A | D134: 1000004 | E134: Aislador Ríg T/ Esp 57-1 C/ Esp y Tuerca | F134: Und. | G134: 1
A135: 1MT-101 | B135: Instalación de Montaje 1ø Línea con Ángulo de 0º a 5º | C135: W-9c | D135: 1002185 | E135: ARANDELA CUADRADA 3" X 3'' PARA TORNILLO DE 5/8"-3/4'' | F135: Und. | G135: 3
A136: 1MT-101 | B136: Instalación de Montaje 1ø Línea con Ángulo de 0º a 5º | C136: W-10c | D136: 1002205 | E136: ARANDELA DE PRESION P/TORNILLO 5/8'' | F136: Und. | G136: 3
A137: 1MT-101 | B137: Instalación de Montaje 1ø Línea con Ángulo de 0º a 5º | C137: C-39C | D137: 1009963 | E137: CONECTOR CUÑA PRESION 2/0 AWG A 2 CU AWG | F137: Und. | G137: 1
A138: 1MT-101 | B138: Instalación de Montaje 1ø Línea con Ángulo de 0º a 5º | C138: GCT-ST1 | D138: 1009789 | E138: GRAPA DE CONEXIÓN DOBLE CABLE DE TIERRA SIN TORNILLO | F138: Und. | G138: 1
A139: 1MT-101 | B139: Instalación de Montaje 1ø Línea con Ángulo de 0º a 5º | C139: I-1A | D139: 1003156 | E139: Perno para aisladores line post 3/4" - 3/4" x 3". | F139: Und. | G139: 1
A140: 1MT-101 | B140: Instalación de Montaje 1ø Línea con Ángulo de 0º a 5º | C140: B-2D | D140: 1002329 | E140: Tornillo Máq Cab Cuad 5/8"x10" | F140: Und. | G140: 2
A141: 1MT-101 | B141: Instalación de Montaje 1ø Línea con Ángulo de 0º a 5º | C141: E-4A | D141: 1004830 | E141: Tuerca cuadrada acero galvanizado para tornillo 5/8”. | F141: Und. | G141: 1
A142: 1MT-101 | B142: Instalación de Montaje 1ø Línea con Ángulo de 0º a 5º | C142: I-2F | D142: 1004822 | E142: Espiga soporte de acero para aislador tipo line-post en punta de poste | F142: Und. | G142: 1
... A219: 1MT-307 | B219: Instalación de Montaje 3ø, (Horizontal) Fin de Linea | C219: CP-02C | D219: 1009782 | E219: Cable de acero cobreado desnudo #2 AWG; 7 hilos | F219: Mts. | G219: 0.5
A220: 1MT-307 | B220: Instalación de Montaje 3ø, (Horizontal) Fin de Linea | C220: C-15C | D220: #N/A | E220: Grapa de retención para conductores #312.8 MCM - #559 MCM | F220: Und. | G220: 3
A221: 1MT-307 | B221: Instalación de Montaje 3ø, (Horizontal) Fin de Linea | C221: AS-22D | D221: 1000005 | E221: Aislador Susp 12.5kV Polimérico | F221: Und. | G221: 3
A222: 1MT-307 | B222: Instalación de Montaje 3ø, (Horizontal) Fin de Linea | C222: W-10C | D222: 1002205 | E222: ARANDELA DE PRESION P/TORNILLO 5/8'' | F222: Und. | G222: 18
A223: 1MT-307 | B223: Instalación de Montaje 3ø, (Horizontal) Fin de Linea | C223: W-10B | D223: 1002201 | E223: Arandela de presión para tornillo de 1/2” | F223: Und. | G223: 1
A224: 1MT-307 | B224: Instalación de Montaje 3ø, (Horizontal) Fin de Linea | C224: C-20D | D224: 1002083 | E224: Cruceta de acero galvanizado, perfil "L", de 3"x 3"x 1/4" x 8' | F224: Und. | G224: 2
A225: 1MT-307 | B225: Instalación de Montaje 3ø, (Horizontal) Fin de Linea | C225: C-26A | D225: 1001892 | E225: Grapa de fijación de cable a superficie plana 1/4" p/conductor Cu 2/0-#8 AWG | F225: Und. | G225: 1
A226: 1MT-307 | B226: Instalación de Montaje 3ø, (Horizontal) Fin de Linea | C226: C-15B | D226: 1000742 | E226: GRAPA DE RETENCION DE ACERO GALVANIZ. PARA COND. DE 1/0AL-ACSR A 4/0AL ACSR | F226: Und. | G226: 1
A227: 1MT-307 | B227: Instalación de Montaje 3ø, (Horizontal) Fin de Linea | C227: B-1C | D227: 1002283 | E227: Tornillo de espaciamiento acero galvanizado 5/8” x 12” | F227: Und. | G227: 5
A228: 1MT-307 | B228: Instalación de Montaje 3ø, (Horizontal) Fin de Linea | C228: E-2A | D228: 1002390 | E228: TUERCA DE OJO OVAL PARA TORNILO DE 5/8" | F228: Und. | G228: 4
A229: 1MT-307 | B229: Instalación de Montaje 3ø, (Horizontal) Fin de Linea | C229: B-6A | D229: 1001241 | E229: Fleje plancha de acero galv. 1-7/32"x 7/32" x 28" | F229: Und. | G229: 4
A230: 1MT-307 | B230: Instalación de Montaje 3ø, (Horizontal) Fin de Linea | C230: W-10A | D230: 1002204 | E230: Arandela de presión para tornillo de 3/8” | F230: Und. | G230: 4
A231: 1MT-307 | B231: Instalación de Montaje 3ø, (Horizontal) Fin de Linea | C231: B-2B | D231: 1002308 | E231: Tornillo de máquina acero galvanizado cabeza cuadrada 1/2" x 12” | F231: Und. | G231: 1
...

Sheet Hoja2
A3: Descripción | B3: Código Material
A4: Cobertor de Líneas MT 12.5kV MVLC 4/0 | B4: 1000568
A5: CONEXIÓN DE CUT-OUT A 4651 | B5: C-40B
A6: CONEXIÓN DE CUT-OUT A 4651 | B6: CAPE
A7: CONEXIÓN DE CUT-OUT A 4651 | B7: CM-01G
A8: Cruceta de acero en semivoladizo para media tensión | B8: B-2D
A9: Cruceta de acero en semivoladizo para media tensión | B9: B-5B
A10: Cruceta de acero en semivoladizo para media tensión | B10: B-7B
A11: Cruceta de acero en semivoladizo para media tensión | B11: C-20D
A12: Cruceta de acero en semivoladizo para media tensión | B12: E-4
A13: Cruceta de acero en semivoladizo para media tensión | B13: GR-10
A14: Cruceta de acero en semivoladizo para media tensión | B14: W-10b
A15: Cruceta de acero en semivoladizo para media tensión | B15: W-10C
A16: Cruceta de acero en semivoladizo para media tensión | B16: W-9C
... A863: POSTE DE HORMIGÓN PRETENSADO VIBRADO 800 DAN-10.5 M(35’) | B863: HPV-800-10
A864: Poste de madera de 60 Pies Clase 2 | B864: 1011408
A865: Puesta a Tierra con Anillo Cerrado para Poste de Hormigon | B865: B-7Y
A866: Puesta a Tierra con Anillo Cerrado para Poste de Hormigon | B866: CP-02C
A867: Puesta a Tierra con Anillo Cerrado para Poste de Hormigon | B867: HA-1B
A868: Puesta a Tierra con Anillo Cerrado para Poste de Hormigon | B868: R-2F
A869: Puesta a Tierra con Anillo Cerrado para Poste de Hormigon | B869: TUB-4B
A870: Puesta a Tierra con Anillo Cerrado para Poste de Hormigon | B870: C-R1D
A871: Puesta a Tierra Interior en Poste de Concreto | B871: B-2O
A872: Puesta a Tierra Interior en Poste de Concreto | B872: CP-02C
A873: Puesta a Tierra Interior en Poste de Concreto | B873: R-2F
A874: Puesta a Tierra Interior en Poste de Concreto | B874: TB-02
A875: Puesta a Tierra Interior en Poste de Concreto | B875: C-R1D
A876: RECONECTADOR AUTOMATICO DE CIRCUITO RE | B876: ITC-22R1
... A892: Intalacion de luminaria led | B892: CM-22D
A893: Intalacion de luminaria led | B893: 1014667
A894: Intalacion de luminaria led | B894: F-5A
A895: INSTALACIÓN.ACOM.240V EN SCMA CON MED.DIPLAY Y TC. | B895: E-2a
A896: INSTALACIÓN.ACOM.240V EN SCMA CON MED.DIPLAY Y TC. | B896: A-5C
A897: INSTALACIÓN.ACOM.240V EN SCMA CON MED.DIPLAY Y TC. | B897: CS-33C
A898: INSTALACIÓN.ACOM.240V EN SCMA CON MED.DIPLAY Y TC. | B898: MMT-240-3H
A899: INSTALACIÓN.ACOM.240V EN SCMA CON MED.DIPLAY Y TC. | B899: MPVC-DIS-240V
A900: INSTALACIÓN.ACOM.240V EN SCMA CON MED.DIPLAY Y TC. | B900: PZ-2C
A901: INSTALACIÓN.ACOM.240V EN SCMA CON MED.DIPLAY Y TC. | B901: TC-002
A902: INSTALACIÓN DE JUMPER AEREO TRIPLEX 4/0 -4/0 | B902: C-6HC
A903: INSTALACIÓN DE JUMPER AEREO TRIPLEX 4/0 -4/0 | B903: CB-11F
...

Sheet TBD1
E2: kkkk
A3: Actividad_Principal | B3: UUTT | C3: Descripcion | D3: Unidad | E3: Suma de Cantidad_Ejecutada
A4: INSTALACIÓN | B4: AL-BT3 | C4: Derivación cable guía Medio Vano | D4: und | E4: 71 | F4: =+VLOOKUP($B4,TB_CALCULO_MAT[UU_TT],1,) -> #N/A
A5: INSTALACIÓN | B5: AL-BT3 | C5: DOBLE TERMINAL DE BAJA TENSIÓN (CABLE NEUTRO) | D5: und | E5: 112 | F5: =+VLOOKUP($B5,TB_CALCULO_MAT[UU_TT],1,) -> #N/A
A6: INSTALACIÓN | B6: AL-BT3 | C6: INSTALACIÓN DE FIN BAJA TENSIÓN | D6: und | E6: 119 | F6: =+VLOOKUP($B6,TB_CALCULO_MAT[UU_TT],1,) -> #N/A
A7: INSTALACIÓN | B7: ART-TUB41 | C7: CONFECCION DE HOYO DE 5` EN TERRENO NORMAL | D7: und | E7: 38 | F7: =+VLOOKUP($B7,TB_CALCULO_MAT[UU_TT],1,) -> #N/A
A8: INSTALACIÓN | B8: ART-TUB41 | C8: EXCAVACIÓN EN TERRENO ROCOSO < 12M | D8: und | E8: 72 | F8: =+VLOOKUP($B8,TB_CALCULO_MAT[UU_TT],1,) -> #N/A
A9: INSTALACIÓN | B9: ART-TUB41 | C9: Excavacion para poste de 30 o vientos De roca | D9: und | E9: 67 | F9: =+VLOOKUP($B9,TB_CALCULO_MAT[UU_TT],1,) -> #N/A
A10: INSTALACIÓN | B10: ART-TUB41 | C10: Instalación de Armado y transp. tubo metalico 4" x 25' para bt | D10: und | E10: 422 | F10: =+VLOOKUP($B10,TB_CALCULO_MAT[UU_TT],1,) -> #N/A
A11: INSTALACIÓN | B11: BT-201-A1 | C11: Instalación de Conexión 4/0 - 2/0 | D11: und | E11: 29 | F11: =+VLOOKUP($B11,TB_CALCULO_MAT[UU_TT],1,) -> BT-201-A1
A12: INSTALACIÓN | B12: BT-201-A1 | C12: Instalación de Conexión 4/0 - 4/0 | D12: und | E12: 75 | F12: =+VLOOKUP($B12,TB_CALCULO_MAT[UU_TT],1,) -> BT-201-A1
A13: INSTALACIÓN | B13: BT-201-A1 | C13: Instalación de Jumper Aereo Triplex 4/0 -4/0 | D13: und | E13: 144 | F13: =+VLOOKUP($B13,TB_CALCULO_MAT[UU_TT],1,) -> BT-201-A1
A14: INSTALACIÓN | B14: BT-201-A1 | C14: INSTALACION JUMPER EN POSTE 4/0 - 4/0 | D14: und | E14: 26 | F14: =+VLOOKUP($B14,TB_CALCULO_MAT[UU_TT],1,) -> BT-201-A1
A15: INSTALACIÓN | B15: CC-4/0-2/01 | C15: Instalación de Conexión 4/0 - 2/0 | D15: und | E15: 206 | F15: =+VLOOKUP($B15,TB_CALCULO_MAT[UU_TT],1,) -> CC-4/0-2/01
... A203: TRANSFERENCIA | B203: TP-2C2 | C203: Transferencia de Tendido de Conductor Triplex 2/0 Neutro 2/0 | D203: ml | E203: 5427 | F203: =+VLOOKUP($B203,TB_CALCULO_MAT[UU_TT],1,) -> #N/A
A204: Total general | E204: 118274 | F204: =+VLOOKUP($B204,TB_CALCULO_MAT[UU_TT],1,) -> #N/A

Sheet Ejecutado
B2: 🔴 TABLA 5 — EJECUTADO DIARIO | ACTUALIZAR CADA DÍA | SOLO AGREGAR FILAS — NUNCA BORRAR
B4: ID_Registro | C4: Codigo_Poste | D4: UUTT | E4: Descripcion | F4: Unidad | G4: Cantidad_Ejecutada | H4: Fecha_Ejecucion | I4: ID_Tarea | J4: ID_Circuito | K4: Nombre_Proyecto | L4: Subestacion | M4: Coordenada_X | N4: Coordenada_Y | O4: Hasta | P4: Actividad_Principal | Q4: Nombre_Tarea | R4: Observaciones
B5: EJ04270 | C5: SPCR-68 | D5: EXC-21 | E5: EXCAVACIÓN EN TERRENO ROCOSO < 12M | F5: und | G5: 2 | H5: 45658 | I5: T441 | J5: SPCR-05 | K5: Proyectos Rehabilitacion de Redes MT-BT y Normalizacion Usuario SPCR-05 | L5: SUB Capotillo | M5: 18.455792 | N5: -69.904762 | P5: INSTALACIÓN | Q5: OBRAS CIVILES
B6: EJ04271 | C6: SPCR-89 | D6: ART-TUB41 | E6: Instalación de Armado y transp. tubo metalico 4" x 25' para bt | F6: und | G6: 2 | H6: 45663 | I6: T441 | J6: SPCR-05 | K6: Proyectos Rehabilitacion de Redes MT-BT y Normalizacion Usuario SPCR-05 | L6: SUB Capotillo | M6: 18.43819 | N6: -69.835244 | P6: INSTALACIÓN | Q6: OBRAS CIVILES
B7: EJ03396 | C7: HAIN-50 | D7: EXC-21 | E7: EXCAVACIÓN EN TERRENO ROCOSO < 12M | F7: und | G7: 1 | H7: 45664 | I7: T391 | J7: HAIN-05 | K7: Proyectos Rehabilitacion de Redes MT-BT y Normalizacion Usuario HAIN-05 | L7: SUB Capotillo | M7: 18.443049 | N7: -69.863516 | P7: INSTALACIÓN | Q7: OBRAS CIVILES
B8: EJ03096 | C8: HAIN-65 | D8: EXC-31 | E8: EXCAVACIÓN EN TERRENO ROCOSO PARA POSTE >12M | F8: und | G8: 1 | H8: 45665 | I8: T361 | J8: HAIN-02 | K8: Proyectos Rehabilitacion de Redes MT-BT y Normalizacion Usuario HAIN-02 | L8: SUB Alma Rosa | M8: 18.523869 | N8: -69.858458 | P8: INSTALACIÓN | Q8: OBRAS CIVILES
B9: EJ02517 | C9: GUAL-11 | D9: EXC-21 | E9: EXCAVACIÓN EN TERRENO ROCOSO < 12M | F9: und | G9: 5 | H9: 45666 | I9: T321 | J9: GUAL-03 | K9: Proyectos Rehabilitacion de Redes MT-BT y Normalizacion Usuario GUAL-03 | L9: SUB Villa Faro | M9: 18.519726 | N9: -69.918148 | P9: INSTALACIÓN | Q9: OBRAS CIVILES
B10: EJ02518 | C10: GUAL-54 | D10: EXC-21 | E10: EXCAVACIÓN EN TERRENO ROCOSO < 12M | F10: und | G10: 4 | H10: 45670 | I10: T321 | J10: GUAL-03 | K10: Proyectos Rehabilitacion de Redes MT-BT y Normalizacion Usuario GUAL-03 | L10: SUB Isabelita | M10: 18.517829 | N10: -69.887159 | P10: INSTALACIÓN | Q10: OBRAS CIVILES
B11: EJ04272 | C11: SPCR-10 | D11: EXC-11 | E11: Excavacion para poste de 30 o vientos De roca | F11: und | G11: 1 | H11: 45670 | I11: T441 | J11: SPCR-05 | K11: Proyectos Rehabilitacion de Redes MT-BT y Normalizacion Usuario SPCR-05 | L11: SUB Capotillo | M11: 18.503987 | N11: -69.878801 | P11: INSTALACIÓN | Q11: OBRAS CIVILES
B12: EJ03097 | C12: HAIN-54 | D12: EXC-31 | E12: EXCAVACIÓN EN TERRENO ROCOSO PARA POSTE >12M | F12: und | G12: 1 | H12: 45671 | I12: T361 | J12: HAIN-02 | K12: Proyectos Rehabilitacion de Redes MT-BT y Normalizacion Usuario HAIN-02 | L12: SUB Los Frailes | M12: 18.44163 | N12: -69.855113 | P12: INSTALACIÓN | Q12: OBRAS CIVILES
B13: EJ03397 | C13: HAIN-57 | D13: EXC-41 | E13: EXCAVACIÓN EN TERRENO ROCOSO PARA POSTE >14M | F13: und | G13: 1 | H13: 45671 | I13: T391 | J13: HAIN-05 | K13: Proyectos Rehabilitacion de Redes MT-BT y Normalizacion Usuario HAIN-05 | L13: SUB Nacional | M13: 18.495502 | N13: -69.920439 | P13: INSTALACIÓN | Q13: OBRAS CIVILES
B14: EJ03538 | C14: SPCR-50 | D14: ZURD-11 | E14: Instalación de excavacion zanja 0.8 x 2.0 m para tubos y conductores URD | F14: und | G14: 5 | H14: 45671 | I14: T401 | J14: SPCR-01 | K14: Proyectos Rehabilitacion de Redes MT-BT y Normalizacion Usuario SPCR-01 | L14: SUB Los Mina Norte | M14: 18.49136 | N14: -69.832257 | P14: INSTALACIÓN | Q14: OBRAS CIVILES
B15: EJ03887 | C15: SPCR-17 | D15: EXC-21 | E15: EXCAVACIÓN EN TERRENO ROCOSO < 12M | F15: und | G15: 2 | H15: 45671 | I15: T421 | J15: SPCR-03 | K15: Proyectos Rehabilitacion de Redes MT-BT y Normalizacion Usuario SPCR-03 | L15: SUB Villa Faro | M15: 18.436503 | N15: -69.90418 | P15: INSTALACIÓN | Q15: OBRAS CIVILES
B16: EJ03098 | C16: HAIN-32 | D16: EXC-41 | E16: EXCAVACIÓN EN TERRENO ROCOSO PARA POSTE >14M | F16: und | G16: 1 | H16: 45673 | I16: T361 | J16: HAIN-02 | K16: Proyectos Rehabilitacion de Redes MT-BT y Normalizacion Usuario HAIN-02 | L16: SUB Los Frailes | M16: 18.495849 | N16: -69.891164 | P16: INSTALACIÓN | Q16: OBRAS CIVILES
... B7112: EJ06999 | C7112: MULT-89 | D7112: PR-2011 | E7112: INSTALACION PUESTA A TIERRA EN POSTE METALICO | F7112: und | G7112: 3 | H7112: 46105 | I7112: T688 | J7112: MULTI-09 | K7112: Rehabilitacion Redes MT-BT Fondo Multilateral MULTI-09 | L7112: SUB Los Tres Brazos | M7112: 18.519066 | N7112: -69.922729 | P7112: INSTALACIÓN | Q7112: PROTECCIONES DE MT

Sheet MATERIALES GENERADOS
D2: X
A3: Código Material | B3: Descripción_MAT | C3: Unidad
A4: 1000004 | B4: Aislador Ríg T/ Esp 57-1 C/ Esp y Tuerca | C4: Und.
A5: 1000017 | B5: Aislador T/ Esp PIN CL55-5 1" | C5: Und.
A6: 1000095 | B6: CABLE COBRE URD #1/0 AISL P/ 15kV | C6: Mts.
A7: 1000411 | B7: Bombilla Sodio Alta Pres 400W 100V HPS | C7: Und.
A8: 1000434 | B8: Luminaria T/ Cobra HPS 400W | C8: Und.
A9: 1000568 | B9: Cobertor de Líneas MT 12.5kV MVLC 4/0 | C9: Mts.
A10: 1001223 | B10: Espiga Acero 3/4"x7 3/4" | C10: Und.
A11: 1001242 | B11: Fleje Plancha Acero 1 1/4x1/4"x28" | C11: Und.
A12: 1002083 | B12: Cruceta Acer 3"x3"x1/4" Perf L 8'-0" | C12: Und.
A13: 1002201 | B13: Arandela Presión P/ Tornillo 1/2'' | C13: Und.
A14: 1002204 | B14: Arandela Presión P/ Tornillo 3/8" | C14: Und.
A15: 1002205 | B15: Arandela Presión P/ Tornillo 5/8'' | C15: Und.
... A28: 2011178 | B28: Gabinete de 18 medidores con GPRS | C28: Und.
A29: B-1F | B29: TORNILLO DE ESPACIAMIENTO CON 4 TUERCAS 5/8" X 18" | C29: Und.
A30: B-2a | B30: TORNILLO DE MAQUINA ACERO GALVANIZADO CABEZA CUADRADA 1/2" X 10" | C30: Und.
A31: A-5C | B31: TARUGO-PERNO ACERADO RECUB. ZINC 5/8" X 3 3/4", PERNO DE 1/2" | C31: Und.
A32: A-5F | B32: TARUGO-PERNOACERADO RECUB.ZINC LONG 13/4",PERNO DE 1/4" | C32: Und.
A33: A-7A | B33: TARUGO PLAST. C/TORNILLO CABEZA HEXAGONAL NO.10-12, LONG. 1" DIAM. 9/32" | C33: Und.
A34: AC-11A | B34: Aislad T/Carr 3x3-1/8 76x80mm 11/16 53-2 | C34: Und.
A35: AD-4B | B35: Pararrayos de distribución de 9 kV; 12.47 kV. Estrella | C35: Und.
A36: AH-11A | B36: CONO DE ANCLAR DE CONCRETO 18" X 6" X 8" | C36: Und.
A37: AM-12C | B37: Conductor de cobre #3/0 AWG tipo THHN | C37: Mts.
A38: AM-12D | B38: Conductor de cobre #300 MCM tipo THHN | C38: Mts.
A39: AMD-01 | B39: Armario para medición industrial (con velo transparente) | C39: Und.
A40: AR-12A | B40: AISLADOR DE PORCELANA TIPO POSTE 15 KV CLASE 57-1 | C40: Und.
A41: AR-13C | B41: Aislador T/ Esp PIN CL56-3 1 3/8" 34.5kV | C41: Und.
B42: Aislador de porcelana tipo poste 35 kV Clase 57-3 | C42: Und.
A43: AS-1A | B43: Aro Seguridad para Sellos tipo Pin | C43: Und.
A44: AS-22D | B44: AISLADOR POLIMÉRICO TIPO SUSPENSIÓN 15 KV | C44: Und.
B45: AISLADOR POLIMERICO TIPO SUSPENSION, 15 KV | C45: Und.
A46: B-10A | B46: Fleje vertical de acero galv. 1-1/2" x 1-1/2" x 3/16"; longitud 39" | C46: Und.
A47: B-10D | B47: Fleje vertical de acero galv. 1-1/2" x 1-1/2" x 3/16"; longitud 54" | C47: Und.
A48: B-1C | B48: Tornillo de espaciamiento acero galvanizado 5/8” x 12” | C48: Und.
B49: TORNILLO DE ESPACIAMIENTO ACERO GALVANIZADO 5/8" X 12". | C49: Und.
A50: B-1D | B50: TORNILLO DE ESPACIAMIENTO ACERO GALVANIZADO 5/8" X 14". | C50: Und.
B51: TORNILLOS DE ESPACIAMIENTO. 4 TUERCAS CUAD.5/8" X 14"(16MMX350MM) | C51: Und.
A52: B-2B | B52: TORNILLO DE MAQUINA ACERO GALVANIZADO CABEZA CUADRADA 1/2" X 12". | C52: Und.
A53: B-2C | B53: Tornillo de máquina acero galvanizado cabeza cuadrada 5/8” x 10” | C53: Und.
...

Sheet BASE DE  CALCULO
A1: UU_TT | B1: Descripción | C1: Código Material | D1: Codigo SAP | E1: Descripción_MAT | F1: Unidad | G1: Cantidad Materiales
A2: 1000568 | B2: Cobertor de Líneas MT 12.5kV MVLC 4/0 | C2: 1000568 | D2: 1000568 | E2: Cobertor de Líneas MT 12.5kV MVLC 4/0 | F2: Mts. | G2: 1.05
A3: 1011408 | B3: Poste de madera de 60 Pies Clase 2 | C3: 1011408 | D3: 1011408 | E3: Poste de madera de 60 Pies Clase 2 | F3: Und. | G3: 1
A4: 1AC-103 | B4: INSTALACIÓN DE ACOMETIDA 120V RED ANTIFRAUDE CON BASE, DESDE LA CAJA DERIVADORA | C4: A-5C | D4: 1002233 | E4: TARUGO-PERNO ACERADO RECUB. ZINC 5/8" X 3 3/4", PERNO DE 1/2" | F4: Und. | G4: 1
A5: 1AC-103 | B5: INSTALACIÓN DE ACOMETIDA 120V RED ANTIFRAUDE CON BASE, DESDE LA CAJA DERIVADORA | C5: A-5F | D5: 1002231 | E5: TARUGO-PERNOACERADO RECUB.ZINC LONG 13/4",PERNO DE 1/4" | F5: Und. | G5: 2
A6: 1AC-103 | B6: INSTALACIÓN DE ACOMETIDA 120V RED ANTIFRAUDE CON BASE, DESDE LA CAJA DERIVADORA | C6: A-7A | D6: 1002236 | E6: TARUGO PLAST. C/TORNILLO CABEZA HEXAGONAL NO.10-12, LONG. 1" DIAM. 9/32" | F6: Und. | G6: 8
A7: 1AC-103 | B7: INSTALACIÓN DE ACOMETIDA 120V RED ANTIFRAUDE CON BASE, DESDE LA CAJA DERIVADORA | C7: AS-1A | D7: 1013657 | E7: Aro Seguridad para Sellos tipo Pin | F7: Und. | G7: 1
A8: 1AC-103 | B8: INSTALACIÓN DE ACOMETIDA 120V RED ANTIFRAUDE CON BASE, DESDE LA CAJA DERIVADORA | C8: BC-100 | D8: 1010780 | E8: Base circular de entrada de 1" para medidor socket FM 2S aluminio fundido | F8: Und. | G8: 1
A9: 1AC-103 | B9: INSTALACIÓN DE ACOMETIDA 120V RED ANTIFRAUDE CON BASE, DESDE LA CAJA DERIVADORA | C9: C-18BK | D9: 1014063 | E9: Abrazadera metálica tipo omega de 3/4" | F9: Und. | G9: 4
A10: 1AC-103 | B10: INSTALACIÓN DE ACOMETIDA 120V RED ANTIFRAUDE CON BASE, DESDE LA CAJA DERIVADORA | C10: CP-02A | D10: 1004213 | E10: Cable de acero cobreado desnudo #6 AWG; 3 hilos | F10: Mts. | G10: 2
A11: 1AC-103 | B11: INSTALACIÓN DE ACOMETIDA 120V RED ANTIFRAUDE CON BASE, DESDE LA CAJA DERIVADORA | C11: C-R1D | D11: 1001831 | E11: Conector Galv P/Varilla Tierra 1/2"-5/8" | F11: Und. | G11: 1
A12: 1AC-103 | B12: INSTALACIÓN DE ACOMETIDA 120V RED ANTIFRAUDE CON BASE, DESDE LA CAJA DERIVADORA | C12: CS-33A | D12: 1000100 | E12: CONDUCTOR CONCÉNTRICO DE ALUMINIO 2 X # 8 AWG | F12: Mts. | G12: 20
A13: 1AC-103 | B13: INSTALACIÓN DE ACOMETIDA 120V RED ANTIFRAUDE CON BASE, DESDE LA CAJA DERIVADORA | C13: DPS-25 | D13: 1000578 | E13: COLLAR DE AMARRE P/ UN HAZ DE ACOM. 25MM C/TARUGO | F13: Und. | G13: 4
A14: 1AC-103 | B14: INSTALACIÓN DE ACOMETIDA 120V RED ANTIFRAUDE CON BASE, DESDE LA CAJA DERIVADORA | C14: E-2a | D14: 1002390 | E14: TUERCA DE OJO OVAL PARA TORNILO DE 5/8" | F14: Und. | G14: 1
A15: 1AC-103 | B15: INSTALACIÓN DE ACOMETIDA 120V RED ANTIFRAUDE CON BASE, DESDE LA CAJA DERIVADORA | C15: MPLC-1A | D15: 1010783 | E15: MEDIDOR CL100,FM1S,120V,2H,MOD.COM.VIA PLC INCLUIDO | F15: Und. | G15: 1
... A40: 1AC-105 | B40: INSTALACIÓN DE ACOMETIDA 120V DESDE RED ANTIFRAUDE CON SMCA CON DISPLAY, TOMACORRIENTE. | C40: E-2a | D40: 1002390 | E40: TUERCA DE OJO OVAL PARA TORNILO DE 5/8" | F40: Und. | G40: 1
A41: 1AC-105 | B41: INSTALACIÓN DE ACOMETIDA 120V DESDE RED ANTIFRAUDE CON SMCA CON DISPLAY, TOMACORRIENTE. | C41: MPVC-120-2H | D41: 1011841 | E41: PANTALLA (DISPLAY) REPETIDORA DE MEDIDOR EN ALTURA CON TELEMEDICION. PANTALLA PARA VER CONSUMO DE CLIENTE, 120V,2 HILOS | F41: Und. | G41: 1
A42: 1AC-105 | B42: INSTALACIÓN DE ACOMETIDA 120V DESDE RED ANTIFRAUDE CON SMCA CON DISPLAY, TOMACORRIENTE. | C42: PZ-2C | D42: 1000816 | E42: Pinza de retención doble | F42: Und. | G42: 2
A43: 1AC-105 | B43: INSTALACIÓN DE ACOMETIDA 120V DESDE RED ANTIFRAUDE CON SMCA CON DISPLAY, TOMACORRIENTE. | C43: TC-002 | D43: 1010450 | E43: Tomacorriente Doble Salida, 125V para superficie | F43: Und. | G43: 1
A44: 1AC-106 | B44: INSTALACIÓN DE ACOMETIDA 240V DESDE RED ANTIFRAUDE CON SMCA CON DISPLAY, TOMACORRIENTE. | C44: A-5C | D44: 1002233 | E44: TARUGO-PERNO ACERADO RECUB. ZINC 5/8" X 3 3/4", PERNO DE 1/2" | F44: Und. | G44: 1
A45: 1AC-106 | B45: INSTALACIÓN DE ACOMETIDA 240V DESDE RED ANTIFRAUDE CON SMCA CON DISPLAY, TOMACORRIENTE. | C45: B-2E | D45: 1002331 | E45: Tornillo de máquina acero galvanizado cabeza cuadrada 5/8” x 14” | F45: Und. | G45: 2
A46: 1AC-106 | B46: INSTALACIÓN DE ACOMETIDA 240V DESDE RED ANTIFRAUDE CON SMCA CON DISPLAY, TOMACORRIENTE. | C46: CS-33C | D46: 1000102 | E46: Conductor concéntrico de Al 3 x #6 AWG | F46: Mts. | G46: 20
A47: 1AC-106 | B47: INSTALACIÓN DE ACOMETIDA 240V DESDE RED ANTIFRAUDE CON SMCA CON DISPLAY, TOMACORRIENTE. | C47: E-2a | D47: 1002390 | E47: TUERCA DE OJO OVAL PARA TORNILO DE 5/8" | F47: Und. | G47: 1
A48: 1AC-106 | B48: INSTALACIÓN DE ACOMETIDA 240V DESDE RED ANTIFRAUDE CON SMCA CON DISPLAY, TOMACORRIENTE. | C48: MPVC-240-2H | D48: 1011842 | E48: PANTALLA (DISPLAY) REPETIDORA DE MEDIDOR EN ALTURA CON TELEMEDICION. PANTALLA PARA VER CONSUMO DE CLIENTE, 240V,2 HILOS | F48: Und. | G48: 1
A49: 1AC-106 | B49: INSTALACIÓN DE ACOMETIDA 240V DESDE RED ANTIFRAUDE CON SMCA CON DISPLAY, TOMACORRIENTE. | C49: PZ-2C | D49: 1000816 | E49: Pinza de retención doble | F49: Und. | G49: 2
A50: 1AC-106 | B50: INSTALACIÓN DE ACOMETIDA 240V DESDE RED ANTIFRAUDE CON SMCA CON DISPLAY, TOMACORRIENTE. | C50: TC-002 | D50: 1010450 | E50: Tomacorriente Doble Salida, 125V para superficie | F50: Und. | G50: 1
A51: 1AL-BT | B51: Instalación de Línea de Baja Tensión en Alineamiento | C51: AC-11A | D51: 1000000 | E51: Aislad T/Carr 3x3-1/8 76x80mm 11/16 53-2 | F51: Und. | G51: 1
A52: 1AL-BT | B52: Instalación de Línea de Baja Tensión en Alineamiento | C52: C-39C | D52: 1009963 | E52: CONECTOR CUÑA PRESION 2/0 AWG A 2 CU AWG | F52: Und. | G52: 1
A53: 1AL-BT | B53: Instalación de Línea de Baja Tensión en Alineamiento | C53: CP-02C | D53: 1009782 | E53: Cable de acero cobreado desnudo #2 AWG; 7 hilos | F53: Mts. | G53: 1
A54: 1AL-BT | B54: Instalación de Línea de Baja Tensión en Alineamiento | C54: GCT-ST1 | D54: 1009789 | E54: GRAPA DE CONEXIÓN DOBLE CABLE DE TIERRA SIN TORNILLO | F54: Und. | G54: 1
A55: 1AL-BT | B55: Instalación de Línea de Baja Tensión en Alineamiento | C55: S-1D | D55: 1002349 | E55: Tornillo P/ Aislador T/ Carrete 5/8"x16" | F55: Und. | G55: 1
A56: 1AL-BT | B56: Instalación de Línea de Baja Tensión en Alineamiento | C56: W-10C | D56: 1002205 | E56: ARANDELA DE PRESION P/TORNILLO 5/8'' | F56: Und. | G56: 1
A57: 1AL-BT | B57: Instalación de Línea de Baja Tensión en Alineamiento | C57: W-7A | D57: 1000050 | E57: Alambre de amarre #4 AWG solido de aluminio | F57: Mts. | G57: 1
A58: 1AL-BT | B58: Instalación de Línea de Baja Tensión en Alineamiento | C58: W-9C | D58: 1002185 | E58: ARANDELA CUADRADA 3" X 3'' PARA TORNILLO DE 5/8"-3/4'' | F58: Und. | G58: 1
A59: 1AP-101 | B59: Instalación Luminaria Con Soporte de 6' en Poste de MT & BT Hasta 400 W | C59: 1000411 | D59: 1000411 | E59: Bombilla Sodio Alta Pres 400W 100V HPS | F59: Und. | G59: 1
A60: 1AP-101 | B60: Instalación Luminaria Con Soporte de 6' en Poste de MT & BT Hasta 400 W | C60: 1000434 | D60: 1000434 | E60: Luminaria T/ Cobra HPS 400W | F60: Und. | G60: 1
A61: 1AP-101 | B61: Instalación Luminaria Con Soporte de 6' en Poste de MT & BT Hasta 400 W | C61: BR-1A | D61: 1000413 | E61: Brazo de 6' para Luminaria de Alumbrado Público | F61: Und. | G61: 1
A62: 1AP-101 | B62: Instalación Luminaria Con Soporte de 6' en Poste de MT & BT Hasta 400 W | C62: CM-22D | D62: 1011853 | E62: Cable de control 3 conductores # 12 AWG | F62: Mts. | G62: 3.5
A63: 1AP-101 | B63: Instalación Luminaria Con Soporte de 6' en Poste de MT & BT Hasta 400 W | C63: F-5F | D63: 1000420 | E63: FOTOCELDA DE 105-305 VOLT. MULTIRANGO NA | F63: Und. | G63: 1
A64: 1AP-101 | B64: Instalación Luminaria Con Soporte de 6' en Poste de MT & BT Hasta 400 W | C64: W-10c | D64: 1002205 | E64: ARANDELA DE PRESION P/TORNILLO 5/8'' | F64: Und. | G64: 2
...

Sheet ACTIVIADES
B1: ID | C1: Sap | D1: Descripción Materiales | E1: Cantidad | N1: Código | O1: Descripción de la actividad | P1: ACTIVIDAD2
B2: 1 | C2: 1002083 | D2: Cruceta Acer 3"x3"x1/4" Perf L 8'-0" | E2: 1 | N2: 1AC-103 | O2: INSTALACIÓN DE ACOMETIDA 120V RED ANTIFRAUDE CON BASE, DESDE LA CAJA DERIVADORA | P2: INSTALACIÓN
B3: 2 | C3: 1000091 | D3: Cable Cobre Estañado #2 AWG Desnudo | E3: 50 | N3: 1AC-104 | O3: INSTALACIÓN DE ACOMETIDA 240V RED ANTIFRAUDE CON BASE, DESDE LA CAJA DERIVADORA | P3: INSTALACIÓN
B4: 3 | C4: 1001241 | D4: Fleje Galv 1-7/32"x7/32"x28" | E4: 2 | H4: C-R1D | I4: 1001831 | J4: Conector Galv P/Varilla Tierra 1/2"-5/8" | N4: 1AC-105 | O4: INSTALACIÓN DE ACOMETIDA 120V DESDE RED ANTIFRAUDE CON SMCA CON DISPLAY, TOMACORRIENTE. | P4: INSTALACIÓN
B5: 4 | C5: 1001763 | D5: Conect Cuña P/ Cond 477 Cairo 4/0-3/0 | E5: 3 | N5: 1AC-106 | O5: INSTALACIÓN DE ACOMETIDA 240V DESDE RED ANTIFRAUDE CON SMCA CON DISPLAY, TOMACORRIENTE. | P5: INSTALACIÓN
B6: 6 | C6: 1001753 | D6: Conect Cu P/ Varilla Tierra 5/8"-1/2" | E6: 5 | N6: 1AL-BT | O6: INSTALACIÓNALACIÓN LÍNEA DE BT EN ALINEAMIENTO | P6: INSTALACIÓN
B7: 7 | C7: 1002283 | D7: Tornillo Esp 4 Tuerc Cuad 5/8"x12" | E7: 4 | N7: 1AP-101 | O7: Instalación Luminaria Con Soporte de 6' en Poste de MT & BT Hasta 400 W | P7: INSTALACIÓN
B8: 8 | C8: 1002308 | D8: Tornillo Máq Cab Cuad 1/2"x12" | E8: 2 | N8: 1AP-102 | O8: Instalación Luminaria Con Soporte de 12' en Poste de MT & BT Hasta 400 W | P8: INSTALACIÓN
B9: 9 | C9: 1002205 | D9: Arandela Presión P/ Tornillo 5/8'' | E9: 2 | N9: 1AP-108 | O9: INSTALACIÓN DE BALASTRO O INGNITOR (ARRANCADOR) | P9: INSTALACIÓN
B10: 10 | C10: 1002191 | D10: Arandela Cuad Pln 2x2"x1/4 Aguj 5/8-3/4" | E10: 2 | N10: 1AP-109 | O10: INSTALACION DE TABLERO O CAJA DE CONTROL DE CONJUNTO DE LUMINARIAS | P10: INSTALACIÓN
B11: 11 | C11: 1000553 | D11: Capacitor Monof T-P 100kVAR 19.92/34.5kV | E11: 3 | N11: 1AP-110 | O11: INSTALACIÓN DE CONTACTOR DE LUMINARIAS EN POSTE (RELAY) | P11: INSTALACIÓN
B12: 12 | C12: 1000614 | D12: Cut-Out 34.5kV 100A 170kV Pocelana | E12: 3 | N12: 1BCON-01 | O12: INSTALACIÓN SOPORTE DE BANCO DE CONDENSADORES. | P12: INSTALACIÓN
B13: 13 | C13: 1001268 | D13: Soporte Banco Capacitor Ac. Galv. 75-95 | E13: 1 | N13: 1BCON-02 | O13: INSTALACIÓN DE CONDENSADORES O CAPACITOR, NO INCLUYE PROTECCIÓN | P13: INSTALACIÓN
B14: 14 | C14: 1001319 | D14: Varilla Puesta Tierra de Cobre 5/8"x8' | E14: 5 | N14: 1BOM-01 | O14: Instalación de Bombillas Hasta 400 W | P14: INSTALACIÓN
B15: 15 | C15: 1000555 | D15: Capacitor Monof T-P 100kVAR 7.2/12.5kV | E15: 3 | N15: 1BOM-02 | O15: Instalación de Bombillas Mayor a 400 W | P15: INSTALACIÓN
N16: 1BREGU-01 | O16: INSTALACIÓN DE BASE PARA BANCO DE REGULADORES/BOOSTER HASTA 3 X 75KV | P16: INSTALACIÓN
N17: 1BREGU-02 | O17: INSTALACIÓN DE BASE PARA BANCO DE REGULADORES/BOOSTER HASTA 3 X 225KV | P17: INSTALACIÓN
N18: 1BREGU-03 | O18: INSTALACIÓN DE BASE PARA BANCO DE REGULADORES/BOOSTER HASTA 3 X 500KV | P18: INSTALACIÓN
N19: 1BREGU-04 | O19: INSTALACIÓN DE BASE PARA BANCO DE REGULADORES/BOOSTER MAYOR A 3 X 500 KV | P19: INSTALACIÓN
N20: 1CABT-03 | O20: INSTALACIÓN DE CAJA DERIVADORA AF (DE 16 A 30 SALIDAS) | P20: INSTALACIÓN
N21: 1CABT-04 | O21: INSTALACIÓN DE CAJA DERIVADORA AF (MAYOR DE 30 SALIDAS ) | P21: INSTALACIÓN
N22: 1CABT-05 | O22: INSTALACIÓN DE DOS CAJAS DERIVADORAS EN UN MISMO PUNTO AF (30 SALIDAS) | P22: INSTALACIÓN
N23: 1CABT-06 | O23: INSTALACIÓN DE DOS CAJAS DERIVADORAS EN UN MISMO PUNTO AF (40 SALIDAS) | P23: INSTALACIÓN
N24: 1CDA-MT | O24: INSTALACIÓNALACIÓN DE CRUCETA DOBLE DE ACERO PARA MEDIA TENSIÓN (CRUCETA DE 8') | P24: INSTALACIÓN
N25: 1CIRS-02 | O25: EMPALME DE URD 1Φ EN REGISTRO | P25: INSTALACIÓN
N26: 1CIRS-03 | O26: INSTALACIÓN TERMINAL EXTERIOR (CONO DE ALIVIO) MONOF. CONDUCTOR ≤ 1/0 BASE EN POSTE | P26: INSTALACIÓN
N27: 1CIRS-04 | O27: INSTALACIÓN TERMINAL EXTERIOR (CONO DE ALIVIO) MONOF. CONDUCTOR 2/0 BASE EN POSTE | P27: INSTALACIÓN
... N37: 1CIRS-14 | O37: INSTALACIÓN TERMINAL INTERIOR (CONO DE ALIVIO) MONOF. CONDUCTOR 559.5MCM | P37: INSTALACIÓN
E38: Código | F38: Descripción de la actividad | G38: UNIDAD | N38: 1CIRS-15 | O38: INSTALACIÓN TERMINAL EXTERIOR (CONO DE ALIVIO) TRIF. CONDUCTOR ≤ 1/0 BASE EN CRUCETA | P38: INSTALACIÓN
E39: 1MT-301/ST | F39: INSTALACIÓN MONTAJE 3Φ, EN ALINEAMIENTO CON ÁNGULO HASTA 5º, 34.5KV | G39: UND | N39: 1CIRS-16 | O39: INSTALACIÓN TERMINAL EXTERIOR (CONO DE ALIVIO) TRIF. CONDUCTOR 2/0 BASE EN CRUCETA | P39: INSTALACIÓN
E40: 1MT-302/ST | F40: INSTALACIÓN MONTAJE 3Φ, LÍNEA CON ÁNGULO DE 6º A 25º, 34.5KV | G40: UND | N40: 1CIRS-17 | O40: INSTALACIÓN TERMINAL EXTERIOR (CONO DE ALIVIO) TRIF. CONDUCTOR 4/0 BASE EN CRUCETA | P40: INSTALACIÓN
E41: 1MT-304-C | F41: INSTALACIÓN 3Ø, LINEA C/ANG 61º A 90º (VERTICAL), CON NEUTRO PRIMARIO | G41: UND | N41: 1CIRS-18 | O41: INSTALACIÓN TERMINAL EXTERIOR (CONO DE ALIVIO) TRIF. CONDUCTOR 465MCM BASE EN CRUCETA | P41: INSTALACIÓN
E42: 1MT-305-F | F42: INSTALACIÓN 3Ø, LINEA C/ANGULO DE 6º A 25º, CON NEUTRO PRIMARIO | G42: UND | N42: 1CIRS-19 | O42: INSTALACIÓN TERMINAL EXTERIOR (CONO DE ALIVIO) TRIF. CONDUCTOR 477MCM BASE EN CRUCETA | P42: INSTALACIÓN
E43: 1MT-307/ST | F43: INSTALACIÓN MONTAJE 3Φ, FIN DE LÍNEA HORIZONTAL, 34.5KV | G43: UND | N43: 1CIRS-20 | O43: INSTALACIÓN TERMINAL EXTERIOR (CONO DE ALIVIO) TRIF. CONDUCTOR 559.5MCM BASE EN CRUCETA | P43: INSTALACIÓN
E44: 1MT-307-F | F44: INSTALACIÓN 3Ø, LINEA C/ANG DE 26º A 60º , CON NEUTRO PRIMARIO (VERTICAL) | G44: UND | N44: 1CO-001 | O44: INSTALACIÓN TENDIDO DE LÍNEA 1/0 AL | P44: INSTALACIÓN
E45: 1MT-308-C | F45: INST 3Ø, ALINEAMIENTO C/DERIVACION 1Ø,C/NEUTRO PRI | G45: UND | N45: 1CO-002 | O45: INSTALACIÓN Tendido DE LÍNEA 2/0 AL | P45: INSTALACIÓN
E46: 1MT-308-F | F46: INST 3Ø, ALINEAM EN F CON DERIVACION 1Ø EN POSTE | G46: UND | N46: 1CO-003 | O46: INSTALACIÓN Tendido DE LÍNEA 4/0 AL | P46: INSTALACIÓN
E47: 1MT-309-C | F47: INST 3Ø,ALINEAM.C/DERIVACION 2Ø,C/NEUTRO PRIMARIO. | G47: UND | N47: 1CO-004 | O47: INSTALACIÓN Tendido DE LÍNEA 465.4 MCM AL | P47: INSTALACIÓN
E48: 1MT-309-F | F48: INSTALACION 3Ø, ALINEAMIENTO CON DERIVACION 2Ø | G48: UND | N48: 1CO-005 | O48: INSTALACIÓN DE TENDIDO DE CONDUCTOR TRIPLEX 2/0 NEUTRO 2/0 | P48: INSTALACIÓN
E49: 1MT-310-C | F49: INST 3Ø, ALINEAM. C/DERIVACION 3Ø,C/NEUTRO PRI | G49: UND | N49: 1CO-006 | O49: INSTALACIÓN DE TENDIDO DE CONDUCTOR TRIPLEX 4/0 NEUTRO 4/0 | P49: INSTALACIÓN
...

Sheet TD_2
A3: Código Material | B3: Codigo SAP | C3: Descripción_MAT | D3: Unidad | E3: Suma de Cantidad Materiales
A4: 1000017 | B4: 1000017 | C4: Aislador T/ Esp PIN CL55-5 1" | D4: Und. | E4: 5
A5: 1000095 | B5: 1000095 | C5: CABLE COBRE URD #1/0 AISL P/ 15kV | D5: Mts. | E5: 2.1
A6: 1000411 | B6: 1000411 | C6: Bombilla Sodio Alta Pres 400W 100V HPS | D6: Und. | E6: 3
A7: 1000434 | B7: 1000434 | C7: Luminaria T/ Cobra HPS 400W | D7: Und. | E7: 3
A8: 1001223 | B8: 1001223 | C8: Espiga Acero 3/4"x7 3/4" | D8: Und. | E8: 2
A9: 1014667 | B9: 1014667 | C9: Luminaria T/Cobra LED 90W | D9: Und. | E9: 1
A10: A-5C | B10: 1002233 | C10: TARUGO-PERNO ACERADO RECUB. ZINC 5/8" X 3 3/4", PERNO DE 1/2" | D10: Und. | E10: 5
A11: A-5F | B11: 1002231 | C11: TARUGO-PERNOACERADO RECUB.ZINC LONG 13/4",PERNO DE 1/4" | D11: Und. | E11: 4
A12: A-7A | B12: 1002236 | C12: TARUGO PLAST. C/TORNILLO CABEZA HEXAGONAL NO.10-12, LONG. 1" DIAM. 9/32" | D12: Und. | E12: 16
A13: AC-11A | B13: 1000000 | C13: Aislad T/Carr 3x3-1/8 76x80mm 11/16 53-2 | D13: Und. | E13: 48
A14: AD-4B | B14: 1000807 | C14: Pararrayos de distribución de 9 kV; 12.47 kV. Estrella | D14: Und. | E14: 72
A15: AH-11A | B15: 1002077 | C15: CONO DE ANCLAR DE CONCRETO 18" X 6" X 8" | D15: Und. | E15: 7
A16: AMD-01 | B16: 1000444 | C16: Armario para medición industrial (con velo transparente) | D16: Und. | E16: 6
A17: AR-12A | B17: 1000004 | C17: AISLADOR DE PORCELANA TIPO POSTE 15 KV CLASE 57-1 | D17: Und. | E17: 166
A18: AR-13C | B18: 1000018 | C18: Aislador T/ Esp PIN CL56-3 1 3/8" 34.5kV | D18: Und. | E18: 13
A19: AS-1A | B19: 1013657 | C19: Aro Seguridad para Sellos tipo Pin | D19: Und. | E19: 2
A20: AS-22D | B20: 1000005 | C20: AISLADOR POLIMERICO TIPO SUSPENSION, 15 KV | D20: Und. | E20: 241
A21: B-10D | B21: 1001244 | C21: Fleje vertical de acero galv. 1-1/2" x 1-1/2" x 3/16"; longitud 54" | D21: Und. | E21: 9
... A51: C-25AB | B51: 1001956 | C51: TERMINAL PIN BIMETALICO PARA CONECTOR CUÑA, CAILBRE 465 MCM, 2 AGUJERO | D51: Und. | E51: 30
A52: C-25BB | B52: (en blanco) | C52: TERMINAL DE COMPRESION BIMETALICO PARA COND. #2 AWG, 1 AGUJERO | D52: Und. | E52: 3
A53: C-25D | B53: 1002008 | C53: TERMINAL DE OJO CERRADO COLOR AMARILLO 10-12 3M | D53: Und. | E53: 32
A54: C-26A | B54: 1001892 | C54: Grapa de fijación de cable a superficie plana 1/4" p/conductor Cu 2/0-#8 AWG | D54: Und. | E54: 33
A55: C-35K | B55: 1004752 | C55: CONECTOR ELÁSTICO TIPO CUÑA 4/0AWG # 2CU AWG | D55: Und. | E55: 48
A56: C-36A | B56: 1009347 | C56: Conector tipo cuña 465.4 MCM – 465.4 MCM | D56: Und. | E56: 14
A57: C-36C | B57: 1001763 | C57: Conector tipo cuña 465.4 MCM – 4/0AWG | D57: Und. | E57: 18
A58: C-36F | B58: 1001764 | C58: Conector elástico tipo cuña 465.4 MCM – 2 Cu AWG | D58: Und. | E58: 30
A59: C-39C | B59: 1009963 | C59: CONECTOR ELÁSTICO TIPO CUÑA 2/0 A #2 AL | D59: Und. | E59: 35
A60: C-39E | B60: 1004753 | C60: Conector elástico tipo cuña 2 – 2 CU AWG | D60: Und. | E60: 2
A61: C-3DC | B61: 1000097 | C61: Cable de Cobre (URD) #2/0 al 33% Aislado para 15 kV | D61: Mts. | E61: 2.1
A62: C-3EA | B62: 1000098 | C62: Cable de Cobre (URD) #4/0 al 33% Aislado para 15 kV | D62: Mts. | E62: 181.15
A63: C-40B | B63: 1001756 | C63: Conector elástico tipo cuña 465.4 MCM con estribo. | D63: Und. | E63: 2
A64: C-41A | B64: 1004345 | C64: Conector elástico tipo cuña de Cobre; varilla 5/8” – 2 AWG Cu. | D64: Und. | E64: 1
... A145: PMC-300-9 | B145: 1012341 | C145: Poste Metálico de Chapa 300 daN - 9 m (30’) | D145: Und. | E145: 6
A146: PMC-400-10 | B146: (en blanco) | C146: Poste Metálico de Chapa 400 daN - 10.5 | E146: 1
A147: PMC-500-10 | B147: 1004250 | C147: Poste Metálico de Chapa 500 daN- 10.5 m(34') | D147: Und. | E147: 3
A148: PMC-500-12 | B148: 1002101 | C148: Poste de Acero Galvanizado 40' 5.0 KN | D148: Und. | E148: 1
A149: PMC-600-12 | B149: 1002102 | C149: Poste Metálico de Chapa 600 daN - 12 m (40’) | D149: Und. | E149: 3
A150: PMC-600-14 | B150: 1002103 | C150: Poste de Acero Galvanizado 45' 6.0 KN | D150: Und. | E150: 1
A151: PMC-700-12 | B151: (en blanco) | C151: Poste Metálico de Chapa 700daN - 12 m (40’) | D151: Und. | E151: 2
...

Sheet BD
A3: ACTIVIDAD PRIMARIA | B3: UU_TT | C3: Descripción | D3: Código Material | E3: Codigo SAP | F3: Descripción_MAT | G3: Unidad | H3: Suma de Cantidad Materiales
A4: INSTALACION | B4: 1AC-103 | C4: INSTALACIÓN DE ACOMETIDA 120V RED ANTIFRAUDE CON BASE, DESDE LA CAJA DERIVADORA | D4: A-5C | E4: 1002233 | F4: TARUGO-PERNO ACERADO RECUB. ZINC 5/8" X 3 3/4", PERNO DE 1/2" | G4: Und. | H4: 1
A5: INSTALACION | B5: 1AC-103 | C5: INSTALACIÓN DE ACOMETIDA 120V RED ANTIFRAUDE CON BASE, DESDE LA CAJA DERIVADORA | D5: A-5F | E5: 1002231 | F5: TARUGO-PERNOACERADO RECUB.ZINC LONG 13/4",PERNO DE 1/4" | G5: Und. | H5: 2
A6: INSTALACION | B6: 1AC-103 | C6: INSTALACIÓN DE ACOMETIDA 120V RED ANTIFRAUDE CON BASE, DESDE LA CAJA DERIVADORA | D6: A-7A | E6: 1002236 | F6: TARUGO PLAST. C/TORNILLO CABEZA HEXAGONAL NO.10-12, LONG. 1" DIAM. 9/32" | G6: Und. | H6: 8
A7: INSTALACION | B7: 1AC-103 | C7: INSTALACIÓN DE ACOMETIDA 120V RED ANTIFRAUDE CON BASE, DESDE LA CAJA DERIVADORA | D7: AS-1A | E7: 1013657 | F7: Aro Seguridad para Sellos tipo Pin | G7: Und. | H7: 1
A8: INSTALACION | B8: 1AC-103 | C8: INSTALACIÓN DE ACOMETIDA 120V RED ANTIFRAUDE CON BASE, DESDE LA CAJA DERIVADORA | D8: BC-100 | E8: 1010780 | F8: Base circular de entrada de 1" para medidor socket FM 2S aluminio fundido | G8: Und. | H8: 1
A9: INSTALACION | B9: 1AC-103 | C9: INSTALACIÓN DE ACOMETIDA 120V RED ANTIFRAUDE CON BASE, DESDE LA CAJA DERIVADORA | D9: C-18BK | E9: 1014063 | F9: Abrazadera metálica tipo omega de 3/4" | G9: Und. | H9: 4
A10: INSTALACION | B10: 1AC-103 | C10: INSTALACIÓN DE ACOMETIDA 120V RED ANTIFRAUDE CON BASE, DESDE LA CAJA DERIVADORA | D10: CP-02A | E10: 1004213 | F10: Cable de acero cobreado desnudo #6 AWG; 3 hilos | G10: Mts. | H10: 2
A11: INSTALACION | B11: 1AC-103 | C11: INSTALACIÓN DE ACOMETIDA 120V RED ANTIFRAUDE CON BASE, DESDE LA CAJA DERIVADORA | D11: C-R1D | E11: 1001831 | F11: Conector Galv P/Varilla Tierra 1/2"-5/8" | G11: Und. | H11: 1
A12: INSTALACION | B12: 1AC-103 | C12: INSTALACIÓN DE ACOMETIDA 120V RED ANTIFRAUDE CON BASE, DESDE LA CAJA DERIVADORA | D12: CS-33A | E12: 1000100 | F12: CONDUCTOR CONCÉNTRICO DE ALUMINIO 2 X # 8 AWG | G12: Mts. | H12: 20
A13: INSTALACION | B13: 1AC-103 | C13: INSTALACIÓN DE ACOMETIDA 120V RED ANTIFRAUDE CON BASE, DESDE LA CAJA DERIVADORA | D13: DPS-25 | E13: 1000578 | F13: COLLAR DE AMARRE P/ UN HAZ DE ACOM. 25MM C/TARUGO | G13: Und. | H13: 4
A14: INSTALACION | B14: 1AC-103 | C14: INSTALACIÓN DE ACOMETIDA 120V RED ANTIFRAUDE CON BASE, DESDE LA CAJA DERIVADORA | D14: E-2A | E14: 1002390 | F14: TUERCA DE OJO OVAL PARA TORNILO DE 5/8" | G14: Und. | H14: 1
A15: INSTALACION | B15: 1AC-103 | C15: INSTALACIÓN DE ACOMETIDA 120V RED ANTIFRAUDE CON BASE, DESDE LA CAJA DERIVADORA | D15: MPLC-1A | E15: 1010783 | F15: MEDIDOR CL100,FM1S,120V,2H,MOD.COM.VIA PLC INCLUIDO | G15: Und. | H15: 1
... A58: INSTALACION | B58: 1AL-BT | C58: Instalación de Línea de Baja Tensión en Alineamiento | D58: W-9C | E58: 1002190 | F58: Arandela Cuad Pln 2 1/4"x2 1/4" 5/8-3/4" | G58: Und. | H58: 1
A59: INSTALACION | B59: 1AP-101 | C59: Instalación Luminaria Con Soporte de 6' en Poste de MT & BT Hasta 400 W | D59: 1000411 | E59: 1000411 | F59: Bombilla Sodio Alta Pres 400W 100V HPS | G59: Und. | H59: 1
A60: INSTALACION | B60: 1AP-101 | C60: Instalación Luminaria Con Soporte de 6' en Poste de MT & BT Hasta 400 W | D60: 1000434 | E60: 1000434 | F60: Luminaria T/ Cobra HPS 400W | G60: Und. | H60: 1
A61: INSTALACION | B61: 1AP-101 | C61: Instalación Luminaria Con Soporte de 6' en Poste de MT & BT Hasta 400 W | D61: BR-1A | E61: 1000413 | F61: Brazo de 6' para Luminaria de Alumbrado Público | G61: Und. | H61: 1
A62: INSTALACION | B62: 1AP-101 | C62: Instalación Luminaria Con Soporte de 6' en Poste de MT & BT Hasta 400 W | D62: CM-22D | E62: 1011853 | F62: Cable de control 3 conductores # 12 AWG | G62: Mts. | H62: 3.5
A63: INSTALACION | B63: 1AP-101 | C63: Instalación Luminaria Con Soporte de 6' en Poste de MT & BT Hasta 400 W | D63: F-5F | E63: 1000420 | F63: FOTOCELDA DE 105-305 VOLT. MULTIRANGO NA | G63: Und. | H63: 1
A64: INSTALACION | B64: 1AP-101 | C64: Instalación Luminaria Con Soporte de 6' en Poste de MT & BT Hasta 400 W | D64: W-10C | E64: 1002205 | F64: ARANDELA DE PRESION P/TORNILLO 5/8'' | G64: Und. | H64: 2
A65: INSTALACION | B65: 1AP-101 | C65: Instalación Luminaria Con Soporte de 6' en Poste de MT & BT Hasta 400 W | D65: W-9B | E65: 1002191 | F65: ARANDELA CUAD.2 1/4" X 2 1/4" ESP.3/16'' (TORN.5/8"-3/4") | G65: Und. | H65: 2
A66: INSTALACION | B66: 1AP-102 | C66: Instalación Luminaria Con Soporte de 12' en Poste de MT & BT Hasta 400 W | D66: 1000411 | E66: 1000411 | F66: Bombilla Sodio Alta Pres 400W 100V HPS | G66: Und. | H66: 1
A67: INSTALACION | B67: 1AP-102 | C67: Instalación Luminaria Con Soporte de 12' en Poste de MT & BT Hasta 400 W | D67: 1000434 | E67: 1000434 | F67: Luminaria T/ Cobra HPS 400W | G67: Und. | H67: 1
A68: INSTALACION | B68: 1AP-102 | C68: Instalación Luminaria Con Soporte de 12' en Poste de MT & BT Hasta 400 W | D68: BR-1A | E68: 1000413 | F68: Brazo de 6' para Luminaria de Alumbrado Público | G68: Und. | H68: 1
A69: INSTALACION | B69: 1AP-102 | C69: Instalación Luminaria Con Soporte de 12' en Poste de MT & BT Hasta 400 W | D69: CM-22D | E69: 1011853 | F69: Cable de control 3 conductores # 12 AWG | G69: Mts. | H69: 3.5
A70: INSTALACION | B70: 1AP-102 | C70: Instalación Luminaria Con Soporte de 12' en Poste de MT & BT Hasta 400 W | D70: F-5F | E70: 1000420 | F70: FOTOCELDA DE 105-305 VOLT. MULTIRANGO NA | G70: Und. | H70: 1
A71: INSTALACION | B71: 1AP-102 | C71: Instalación Luminaria Con Soporte de 12' en Poste de MT & BT Hasta 400 W | D71: W-10C | E71: 1002205 | F71: ARANDELA DE PRESION P/TORNILLO 5/8'' | G71: Und. | H71: 2
A72: INSTALACION | B72: 1AP-102 | C72: Instalación Luminaria Con Soporte de 12' en Poste de MT & BT Hasta 400 W | D72: W-9B | E72: 1002191 | F72: ARANDELA CUAD.2 1/4" X 2 1/4" ESP.3/16'' (TORN.5/8"-3/4") | G72: Und. | H72: 2
A73: INSTALACION | B73: 1BCON-01 | C73: INSTALACIÓN SOPORTE DE BANCO DE CONDENSADORES. | D73: 1000091 | E73: 1000091 | F73: Cable Cobre Estañado #2 AWG Desnudo | G73: Mts. | H73: 20
A74: INSTALACION | B74: 1BCON-01 | C74: INSTALACIÓN SOPORTE DE BANCO DE CONDENSADORES. | D74: 1000555 | E74: 1000555 | F74: Capacitor Monof T-P 100kVAR 7.2/12.5kV | G74: Und. | H74: 3
A75: INSTALACION | B75: 1BCON-01 | C75: INSTALACIÓN SOPORTE DE BANCO DE CONDENSADORES. | D75: 1001268 | E75: 1001268 | F75: Soporte Banco Capacitor Ac. Galv. 75-95 | G75: Und. | H75: 1
A76: INSTALACION | B76: 1BCON-01 | C76: INSTALACIÓN SOPORTE DE BANCO DE CONDENSADORES. | D76: AD-4B | E76: 1000807 | F76: Pararrayos de distribución de 9 kV; 12.47 kV. Estrella | G76: Und. | H76: 3
A77: INSTALACION | B77: 1BCON-01 | C77: INSTALACIÓN SOPORTE DE BANCO DE CONDENSADORES. | D77: B-2B | E77: 1002308 | F77: TORNILLO DE MAQUINA ACERO GALVANIZADO CABEZA CUADRADA 1/2" X 12". | G77: Und. | H77: 1
A78: INSTALACION | B78: 1BCON-01 | C78: INSTALACIÓN SOPORTE DE BANCO DE CONDENSADORES. | D78: B-4A | E78: 1001778 | F78: Conect Perno Part P/ Cabl No.2 al 2/0 Cu | G78: Und. | H78: 2
A79: INSTALACION | B79: 1BCON-01 | C79: INSTALACIÓN SOPORTE DE BANCO DE CONDENSADORES. | D79: B‐5A | E79: 1002325 | F79: Tornillo de máquina acero galvanizado cabeza hexagonal 3/8” x 2” | G79: Und. | H79: 2
A80: INSTALACION | B80: 1BCON-01 | C80: INSTALACIÓN SOPORTE DE BANCO DE CONDENSADORES. | D80: B-6A | E80: 1001241 | F80: Fleje plancha de acero galv. 1-7/32"x 7/32" x 28" | G80: Und. | H80: 2
A81: INSTALACION | B81: 1BCON-01 | C81: INSTALACIÓN SOPORTE DE BANCO DE CONDENSADORES. | D81: C-20D | E81: 1002083 | F81: Cruceta de acero galvanizado, perfil "L", de 3"x 3"x 1/4" x 8' | G81: Und. | H81: 1
A82: INSTALACION | B82: 1BCON-01 | C82: INSTALACIÓN SOPORTE DE BANCO DE CONDENSADORES. | D82: C-6HC | E82: 1001757 | F82: CONECTOR TIPO CUÑA DE ALUMINO DE 4/0 DERIVACION 4/0 A 3/0 AWG | G82: Und. | H82: 3
A83: INSTALACION | B83: 1BCON-01 | C83: INSTALACIÓN SOPORTE DE BANCO DE CONDENSADORES. | D83: C-R1D | E83: 1001831 | F83: Conector Galv P/Varilla Tierra 1/2"-5/8" | G83: Und. | H83: 3
A84: INSTALACION | B84: 1BCON-01 | C84: INSTALACIÓN SOPORTE DE BANCO DE CONDENSADORES. | D84: FU-12AB | E84: 1000627 | F84: Fusible 100A (10/24kV) 442mm | G84: Und. | H84: 3
...

Sheet UUTT2
A1: ACTIVIDAD PRIMARIA | B1: UU_TT | C1: Descripción | D1: Código Material | E1: Codigo SAP | F1: Descripción_MAT | G1: Unidad | H1: Cantidad Materiales
A2: INSTALACION | B2: 1AC-103 | C2: INSTALACIÓN DE ACOMETIDA 120V RED ANTIFRAUDE CON BASE, DESDE LA CAJA DERIVADORA | D2: A-5C | E2: 1002233 | F2: TARUGO-PERNO ACERADO RECUB. ZINC 5/8" X 3 3/4", PERNO DE 1/2" | G2: Und. | H2: 1
A3: INSTALACION | B3: 1AC-103 | C3: INSTALACIÓN DE ACOMETIDA 120V RED ANTIFRAUDE CON BASE, DESDE LA CAJA DERIVADORA | D3: A-5F | E3: 1002231 | F3: TARUGO-PERNOACERADO RECUB.ZINC LONG 13/4",PERNO DE 1/4" | G3: Und. | H3: 2
A4: INSTALACION | B4: 1AC-103 | C4: INSTALACIÓN DE ACOMETIDA 120V RED ANTIFRAUDE CON BASE, DESDE LA CAJA DERIVADORA | D4: A-7A | E4: 1002236 | F4: TARUGO PLAST. C/TORNILLO CABEZA HEXAGONAL NO.10-12, LONG. 1" DIAM. 9/32" | G4: Und. | H4: 8
A5: INSTALACION | B5: 1AC-103 | C5: INSTALACIÓN DE ACOMETIDA 120V RED ANTIFRAUDE CON BASE, DESDE LA CAJA DERIVADORA | D5: AS-1A | E5: 1013657 | F5: Aro Seguridad para Sellos tipo Pin | G5: Und. | H5: 1
A6: INSTALACION | B6: 1AC-103 | C6: INSTALACIÓN DE ACOMETIDA 120V RED ANTIFRAUDE CON BASE, DESDE LA CAJA DERIVADORA | D6: BC-100 | E6: 1010780 | F6: Base circular de entrada de 1" para medidor socket FM 2S aluminio fundido | G6: Und. | H6: 1
A7: INSTALACION | B7: 1AC-103 | C7: INSTALACIÓN DE ACOMETIDA 120V RED ANTIFRAUDE CON BASE, DESDE LA CAJA DERIVADORA | D7: C-18BK | E7: 1014063 | F7: Abrazadera metálica tipo omega de 3/4" | G7: Und. | H7: 4
A8: INSTALACION | B8: 1AC-103 | C8: INSTALACIÓN DE ACOMETIDA 120V RED ANTIFRAUDE CON BASE, DESDE LA CAJA DERIVADORA | D8: CP-02A | E8: 1004213 | F8: Cable de acero cobreado desnudo #6 AWG; 3 hilos | G8: Mts. | H8: 2
A9: INSTALACION | B9: 1AC-103 | C9: INSTALACIÓN DE ACOMETIDA 120V RED ANTIFRAUDE CON BASE, DESDE LA CAJA DERIVADORA | D9: C-R1D | E9: 1001831 | F9: Conector Galv P/Varilla Tierra 1/2"-5/8" | G9: Und. | H9: 1
A10: INSTALACION | B10: 1AC-103 | C10: INSTALACIÓN DE ACOMETIDA 120V RED ANTIFRAUDE CON BASE, DESDE LA CAJA DERIVADORA | D10: CS-33A | E10: 1000100 | F10: CONDUCTOR CONCÉNTRICO DE ALUMINIO 2 X # 8 AWG | G10: Mts. | H10: 20
A11: INSTALACION | B11: 1AC-103 | C11: INSTALACIÓN DE ACOMETIDA 120V RED ANTIFRAUDE CON BASE, DESDE LA CAJA DERIVADORA | D11: DPS-25 | E11: 1000578 | F11: COLLAR DE AMARRE P/ UN HAZ DE ACOM. 25MM C/TARUGO | G11: Und. | H11: 4
A12: INSTALACION | B12: 1AC-103 | C12: INSTALACIÓN DE ACOMETIDA 120V RED ANTIFRAUDE CON BASE, DESDE LA CAJA DERIVADORA | D12: E-2A | E12: 1002390 | F12: TUERCA DE OJO OVAL PARA TORNILO DE 5/8" | G12: Und. | H12: 1
A13: INSTALACION | B13: 1AC-103 | C13: INSTALACIÓN DE ACOMETIDA 120V RED ANTIFRAUDE CON BASE, DESDE LA CAJA DERIVADORA | D13: MPLC-1A | E13: 1010783 | F13: MEDIDOR CL100,FM1S,120V,2H,MOD.COM.VIA PLC INCLUIDO | G13: Und. | H13: 1
... A56: INSTALACION | B56: 1AL-BT | C56: Instalación de Línea de Baja Tensión en Alineamiento | D56: W-9C | E56: 1002190 | F56: Arandela Cuad Pln 2 1/4"x2 1/4" 5/8-3/4" | G56: Und. | H56: 1
A57: INSTALACION | B57: 1AP-101 | C57: Instalación Luminaria Con Soporte de 6' en Poste de MT & BT Hasta 400 W | D57: 1000411 | E57: 1000411 | F57: Bombilla Sodio Alta Pres 400W 100V HPS | G57: Und. | H57: 1
A58: INSTALACION | B58: 1AP-101 | C58: Instalación Luminaria Con Soporte de 6' en Poste de MT & BT Hasta 400 W | D58: 1000434 | E58: 1000434 | F58: Luminaria T/ Cobra HPS 400W | G58: Und. | H58: 1
A59: INSTALACION | B59: 1AP-101 | C59: Instalación Luminaria Con Soporte de 6' en Poste de MT & BT Hasta 400 W | D59: BR-1A | E59: 1000413 | F59: Brazo de 6' para Luminaria de Alumbrado Público | G59: Und. | H59: 1
A60: INSTALACION | B60: 1AP-101 | C60: Instalación Luminaria Con Soporte de 6' en Poste de MT & BT Hasta 400 W | D60: CM-22D | E60: 1011853 | F60: Cable de control 3 conductores # 12 AWG | G60: Mts. | H60: 3.5
A61: INSTALACION | B61: 1AP-101 | C61: Instalación Luminaria Con Soporte de 6' en Poste de MT & BT Hasta 400 W | D61: F-5F | E61: 1000420 | F61: FOTOCELDA DE 105-305 VOLT. MULTIRANGO NA | G61: Und. | H61: 1
A62: INSTALACION | B62: 1AP-101 | C62: Instalación Luminaria Con Soporte de 6' en Poste de MT & BT Hasta 400 W | D62: W-10C | E62: 1002205 | F62: Arandela Presión P/ Tornillo 5/8'' | G62: Und. | H62: 2
